ERROR 2021-12-29 01:47:08,320 views 68395 139911559091968 {'tickerCompany': [ErrorDetail(string='company with this tickerCompany already exists.', code='unique')]}
ERROR 2021-12-29 01:48:19,342 views 68614 139692327147264 {'tickerCompany': [ErrorDetail(string='company with this tickerCompany already exists.', code='unique')]}
ERROR 2021-12-29 01:48:47,486 views 68614 139692327147264 {'tickerCompany': [ErrorDetail(string='company with this tickerCompany already exists.', code='unique')]}
ERROR 2021-12-29 01:50:44,254 views 68614 139692327147264 {'nameCompany': [ErrorDetail(string='Ensure this field has no more than 50 characters.', code='max_length')], 'tickerCompany': [ErrorDetail(string='company with this tickerCompany already exists.', code='unique')]}
ERROR 2021-12-29 01:51:13,197 views 68614 139692327147264 {'nameCompany': [ErrorDetail(string='Ensure this field has no more than 50 characters.', code='max_length')]}
ERROR 2021-12-29 01:51:44,853 views 68614 139692327147264 {'nameCompany': [ErrorDetail(string='Ensure this field has no more than 50 characters.', code='max_length')]}
ERROR 2021-12-29 01:57:04,059 views 69684 139678091675392 {'nameCompany': [ErrorDetail(string='Ensure this field has no more than 50 characters.', code='max_length')]}
ERROR 2021-12-29 01:57:16,489 views 69684 139678091675392 {'tickerCompany': [ErrorDetail(string='company with this tickerCompany already exists.', code='unique')]}
ERROR 2021-12-29 01:58:54,715 views 69987 140235162355456 {'tickerCompany': [ErrorDetail(string='company with this tickerCompany already exists.', code='unique')]}
ERROR 2021-12-29 02:10:01,497 views 70911 140102273701632 {'tickerCompany': [ErrorDetail(string='company with this tickerCompany already exists.', code='unique')]}
ERROR 2021-12-29 02:10:01,538 log 70911 140102273701632 Internal Server Error: /api/company/
Traceback (most recent call last):
  File "/home/stocklap216/anaconda3/envs/django_env/lib/python3.7/site-packages/django/core/handlers/exception.py", line 47, in inner
    response = get_response(request)
  File "/home/stocklap216/anaconda3/envs/django_env/lib/python3.7/site-packages/django/core/handlers/base.py", line 204, in _get_response
    response = response.render()
  File "/home/stocklap216/anaconda3/envs/django_env/lib/python3.7/site-packages/django/template/response.py", line 105, in render
    self.content = self.rendered_content
  File "/home/stocklap216/anaconda3/envs/django_env/lib/python3.7/site-packages/rest_framework/response.py", line 70, in rendered_content
    ret = renderer.render(self.data, accepted_media_type, context)
  File "/home/stocklap216/anaconda3/envs/django_env/lib/python3.7/site-packages/rest_framework/renderers.py", line 103, in render
    allow_nan=not self.strict, separators=separators
  File "/home/stocklap216/anaconda3/envs/django_env/lib/python3.7/site-packages/rest_framework/utils/json.py", line 25, in dumps
    return json.dumps(*args, **kwargs)
  File "/home/stocklap216/anaconda3/envs/django_env/lib/python3.7/json/__init__.py", line 238, in dumps
    **kw).encode(obj)
  File "/home/stocklap216/anaconda3/envs/django_env/lib/python3.7/json/encoder.py", line 199, in encode
    chunks = self.iterencode(o, _one_shot=True)
  File "/home/stocklap216/anaconda3/envs/django_env/lib/python3.7/json/encoder.py", line 257, in iterencode
    return _iterencode(o, 0)
  File "/home/stocklap216/anaconda3/envs/django_env/lib/python3.7/site-packages/rest_framework/utils/encoders.py", line 67, in default
    return super().default(obj)
  File "/home/stocklap216/anaconda3/envs/django_env/lib/python3.7/json/encoder.py", line 179, in default
    raise TypeError(f'Object of type {o.__class__.__name__} '
TypeError: Object of type type is not JSON serializable
ERROR 2021-12-29 02:10:01,539 basehttp 70911 140102273701632 "POST /api/company/ HTTP/1.1" 500 102288
ERROR 2021-12-29 02:10:15,595 views 71010 140141629384448 {'tickerCompany': [ErrorDetail(string='company with this tickerCompany already exists.', code='unique')]}
ERROR 2021-12-29 02:13:26,428 log 71345 139691437557504 Internal Server Error: /api/company/
Traceback (most recent call last):
  File "/home/stocklap216/anaconda3/envs/django_env/lib/python3.7/site-packages/django/core/handlers/exception.py", line 47, in inner
    response = get_response(request)
  File "/home/stocklap216/anaconda3/envs/django_env/lib/python3.7/site-packages/django/core/handlers/base.py", line 204, in _get_response
    response = response.render()
  File "/home/stocklap216/anaconda3/envs/django_env/lib/python3.7/site-packages/django/template/response.py", line 105, in render
    self.content = self.rendered_content
  File "/home/stocklap216/anaconda3/envs/django_env/lib/python3.7/site-packages/rest_framework/response.py", line 70, in rendered_content
    ret = renderer.render(self.data, accepted_media_type, context)
  File "/home/stocklap216/anaconda3/envs/django_env/lib/python3.7/site-packages/rest_framework/renderers.py", line 103, in render
    allow_nan=not self.strict, separators=separators
  File "/home/stocklap216/anaconda3/envs/django_env/lib/python3.7/site-packages/rest_framework/utils/json.py", line 25, in dumps
    return json.dumps(*args, **kwargs)
  File "/home/stocklap216/anaconda3/envs/django_env/lib/python3.7/json/__init__.py", line 238, in dumps
    **kw).encode(obj)
  File "/home/stocklap216/anaconda3/envs/django_env/lib/python3.7/json/encoder.py", line 199, in encode
    chunks = self.iterencode(o, _one_shot=True)
  File "/home/stocklap216/anaconda3/envs/django_env/lib/python3.7/json/encoder.py", line 257, in iterencode
    return _iterencode(o, 0)
  File "/home/stocklap216/anaconda3/envs/django_env/lib/python3.7/site-packages/rest_framework/utils/encoders.py", line 67, in default
    return super().default(obj)
  File "/home/stocklap216/anaconda3/envs/django_env/lib/python3.7/json/encoder.py", line 179, in default
    raise TypeError(f'Object of type {o.__class__.__name__} '
TypeError: Object of type property is not JSON serializable
ERROR 2021-12-29 02:13:26,429 basehttp 71345 139691437557504 "POST /api/company/ HTTP/1.1" 500 101947
ERROR 2021-12-29 02:13:35,599 log 71345 139691437557504 Internal Server Error: /api/company/
Traceback (most recent call last):
  File "/home/stocklap216/anaconda3/envs/django_env/lib/python3.7/site-packages/django/core/handlers/exception.py", line 47, in inner
    response = get_response(request)
  File "/home/stocklap216/anaconda3/envs/django_env/lib/python3.7/site-packages/django/core/handlers/base.py", line 204, in _get_response
    response = response.render()
  File "/home/stocklap216/anaconda3/envs/django_env/lib/python3.7/site-packages/django/template/response.py", line 105, in render
    self.content = self.rendered_content
  File "/home/stocklap216/anaconda3/envs/django_env/lib/python3.7/site-packages/rest_framework/response.py", line 70, in rendered_content
    ret = renderer.render(self.data, accepted_media_type, context)
  File "/home/stocklap216/anaconda3/envs/django_env/lib/python3.7/site-packages/rest_framework/renderers.py", line 103, in render
    allow_nan=not self.strict, separators=separators
  File "/home/stocklap216/anaconda3/envs/django_env/lib/python3.7/site-packages/rest_framework/utils/json.py", line 25, in dumps
    return json.dumps(*args, **kwargs)
  File "/home/stocklap216/anaconda3/envs/django_env/lib/python3.7/json/__init__.py", line 238, in dumps
    **kw).encode(obj)
  File "/home/stocklap216/anaconda3/envs/django_env/lib/python3.7/json/encoder.py", line 199, in encode
    chunks = self.iterencode(o, _one_shot=True)
  File "/home/stocklap216/anaconda3/envs/django_env/lib/python3.7/json/encoder.py", line 257, in iterencode
    return _iterencode(o, 0)
  File "/home/stocklap216/anaconda3/envs/django_env/lib/python3.7/site-packages/rest_framework/utils/encoders.py", line 67, in default
    return super().default(obj)
  File "/home/stocklap216/anaconda3/envs/django_env/lib/python3.7/json/encoder.py", line 179, in default
    raise TypeError(f'Object of type {o.__class__.__name__} '
TypeError: Object of type property is not JSON serializable
ERROR 2021-12-29 02:13:35,599 basehttp 71345 139691437557504 "POST /api/company/ HTTP/1.1" 500 101947
ERROR 2021-12-29 02:52:01,692 log 77352 140222128215808 Internal Server Error: /api/company/
Traceback (most recent call last):
  File "/home/stocklap216/anaconda3/envs/django_env/lib/python3.7/site-packages/django/core/handlers/exception.py", line 47, in inner
    response = get_response(request)
  File "/home/stocklap216/anaconda3/envs/django_env/lib/python3.7/site-packages/django/core/handlers/base.py", line 181, in _get_response
    response = wrapped_callback(request, *callback_args, **callback_kwargs)
  File "/home/stocklap216/anaconda3/envs/django_env/lib/python3.7/site-packages/django/views/decorators/csrf.py", line 54, in wrapped_view
    return view_func(*args, **kwargs)
  File "/home/stocklap216/anaconda3/envs/django_env/lib/python3.7/site-packages/rest_framework/viewsets.py", line 125, in view
    return self.dispatch(request, *args, **kwargs)
  File "/home/stocklap216/anaconda3/envs/django_env/lib/python3.7/site-packages/rest_framework/views.py", line 509, in dispatch
    response = self.handle_exception(exc)
  File "/home/stocklap216/anaconda3/envs/django_env/lib/python3.7/site-packages/rest_framework/views.py", line 469, in handle_exception
    self.raise_uncaught_exception(exc)
  File "/home/stocklap216/anaconda3/envs/django_env/lib/python3.7/site-packages/rest_framework/views.py", line 480, in raise_uncaught_exception
    raise exc
  File "/home/stocklap216/anaconda3/envs/django_env/lib/python3.7/site-packages/rest_framework/views.py", line 506, in dispatch
    response = handler(request, *args, **kwargs)
  File "/home/stocklap216/Documentos/Vacant/DJ/FlinkTest/backend/FlinkBackend/backendCRUD/views.py", line 68, in list
    print(serializer.data)
  File "/home/stocklap216/anaconda3/envs/django_env/lib/python3.7/site-packages/rest_framework/serializers.py", line 745, in data
    ret = super().data
  File "/home/stocklap216/anaconda3/envs/django_env/lib/python3.7/site-packages/rest_framework/serializers.py", line 246, in data
    self._data = self.to_representation(self.instance)
  File "/home/stocklap216/anaconda3/envs/django_env/lib/python3.7/site-packages/rest_framework/serializers.py", line 664, in to_representation
    self.child.to_representation(item) for item in iterable
TypeError: 'Company' object is not iterable
ERROR 2021-12-29 02:52:01,776 basehttp 77352 140222128215808 "GET /api/company/ HTTP/1.1" 500 109241
ERROR 2021-12-29 02:53:19,679 log 77574 140680597440256 Internal Server Error: /api/company/
Traceback (most recent call last):
  File "/home/stocklap216/anaconda3/envs/django_env/lib/python3.7/site-packages/django/core/handlers/exception.py", line 47, in inner
    response = get_response(request)
  File "/home/stocklap216/anaconda3/envs/django_env/lib/python3.7/site-packages/django/core/handlers/base.py", line 181, in _get_response
    response = wrapped_callback(request, *callback_args, **callback_kwargs)
  File "/home/stocklap216/anaconda3/envs/django_env/lib/python3.7/site-packages/django/views/decorators/csrf.py", line 54, in wrapped_view
    return view_func(*args, **kwargs)
  File "/home/stocklap216/anaconda3/envs/django_env/lib/python3.7/site-packages/rest_framework/viewsets.py", line 125, in view
    return self.dispatch(request, *args, **kwargs)
  File "/home/stocklap216/anaconda3/envs/django_env/lib/python3.7/site-packages/rest_framework/views.py", line 509, in dispatch
    response = self.handle_exception(exc)
  File "/home/stocklap216/anaconda3/envs/django_env/lib/python3.7/site-packages/rest_framework/views.py", line 469, in handle_exception
    self.raise_uncaught_exception(exc)
  File "/home/stocklap216/anaconda3/envs/django_env/lib/python3.7/site-packages/rest_framework/views.py", line 480, in raise_uncaught_exception
    raise exc
  File "/home/stocklap216/anaconda3/envs/django_env/lib/python3.7/site-packages/rest_framework/views.py", line 506, in dispatch
    response = handler(request, *args, **kwargs)
  File "/home/stocklap216/Documentos/Vacant/DJ/FlinkTest/backend/FlinkBackend/backendCRUD/views.py", line 69, in list
    return Response(serializer.data,status=HTTP_202_ACCEPTED)
  File "/home/stocklap216/anaconda3/envs/django_env/lib/python3.7/site-packages/rest_framework/serializers.py", line 745, in data
    ret = super().data
  File "/home/stocklap216/anaconda3/envs/django_env/lib/python3.7/site-packages/rest_framework/serializers.py", line 246, in data
    self._data = self.to_representation(self.instance)
  File "/home/stocklap216/anaconda3/envs/django_env/lib/python3.7/site-packages/rest_framework/serializers.py", line 664, in to_representation
    self.child.to_representation(item) for item in iterable
TypeError: 'Company' object is not iterable
ERROR 2021-12-29 02:53:19,680 basehttp 77574 140680597440256 "GET /api/company/ HTTP/1.1" 500 109313
ERROR 2021-12-29 02:54:24,540 log 77834 140587044656896 Internal Server Error: /api/company/
Traceback (most recent call last):
  File "/home/stocklap216/anaconda3/envs/django_env/lib/python3.7/site-packages/django/core/handlers/exception.py", line 47, in inner
    response = get_response(request)
  File "/home/stocklap216/anaconda3/envs/django_env/lib/python3.7/site-packages/django/core/handlers/base.py", line 204, in _get_response
    response = response.render()
  File "/home/stocklap216/anaconda3/envs/django_env/lib/python3.7/site-packages/django/template/response.py", line 105, in render
    self.content = self.rendered_content
  File "/home/stocklap216/anaconda3/envs/django_env/lib/python3.7/site-packages/rest_framework/response.py", line 70, in rendered_content
    ret = renderer.render(self.data, accepted_media_type, context)
  File "/home/stocklap216/anaconda3/envs/django_env/lib/python3.7/site-packages/rest_framework/renderers.py", line 103, in render
    allow_nan=not self.strict, separators=separators
  File "/home/stocklap216/anaconda3/envs/django_env/lib/python3.7/site-packages/rest_framework/utils/json.py", line 25, in dumps
    return json.dumps(*args, **kwargs)
  File "/home/stocklap216/anaconda3/envs/django_env/lib/python3.7/json/__init__.py", line 238, in dumps
    **kw).encode(obj)
  File "/home/stocklap216/anaconda3/envs/django_env/lib/python3.7/json/encoder.py", line 199, in encode
    chunks = self.iterencode(o, _one_shot=True)
  File "/home/stocklap216/anaconda3/envs/django_env/lib/python3.7/json/encoder.py", line 257, in iterencode
    return _iterencode(o, 0)
  File "/home/stocklap216/anaconda3/envs/django_env/lib/python3.7/site-packages/rest_framework/utils/encoders.py", line 67, in default
    return super().default(obj)
  File "/home/stocklap216/anaconda3/envs/django_env/lib/python3.7/json/encoder.py", line 179, in default
    raise TypeError(f'Object of type {o.__class__.__name__} '
TypeError: Object of type ListSerializer is not JSON serializable
ERROR 2021-12-29 02:54:24,542 basehttp 77834 140587044656896 "GET /api/company/ HTTP/1.1" 500 106861
ERROR 2021-12-29 02:55:34,395 log 78054 140054739506944 Internal Server Error: /api/company/
Traceback (most recent call last):
  File "/home/stocklap216/anaconda3/envs/django_env/lib/python3.7/site-packages/django/core/handlers/exception.py", line 47, in inner
    response = get_response(request)
  File "/home/stocklap216/anaconda3/envs/django_env/lib/python3.7/site-packages/django/core/handlers/base.py", line 181, in _get_response
    response = wrapped_callback(request, *callback_args, **callback_kwargs)
  File "/home/stocklap216/anaconda3/envs/django_env/lib/python3.7/site-packages/django/views/decorators/csrf.py", line 54, in wrapped_view
    return view_func(*args, **kwargs)
  File "/home/stocklap216/anaconda3/envs/django_env/lib/python3.7/site-packages/rest_framework/viewsets.py", line 125, in view
    return self.dispatch(request, *args, **kwargs)
  File "/home/stocklap216/anaconda3/envs/django_env/lib/python3.7/site-packages/rest_framework/views.py", line 509, in dispatch
    response = self.handle_exception(exc)
  File "/home/stocklap216/anaconda3/envs/django_env/lib/python3.7/site-packages/rest_framework/views.py", line 469, in handle_exception
    self.raise_uncaught_exception(exc)
  File "/home/stocklap216/anaconda3/envs/django_env/lib/python3.7/site-packages/rest_framework/views.py", line 480, in raise_uncaught_exception
    raise exc
  File "/home/stocklap216/anaconda3/envs/django_env/lib/python3.7/site-packages/rest_framework/views.py", line 506, in dispatch
    response = handler(request, *args, **kwargs)
  File "/home/stocklap216/Documentos/Vacant/DJ/FlinkTest/backend/FlinkBackend/backendCRUD/views.py", line 69, in list
    return Response(serializer.data.values,status=HTTP_202_ACCEPTED)
  File "/home/stocklap216/anaconda3/envs/django_env/lib/python3.7/site-packages/rest_framework/serializers.py", line 745, in data
    ret = super().data
  File "/home/stocklap216/anaconda3/envs/django_env/lib/python3.7/site-packages/rest_framework/serializers.py", line 246, in data
    self._data = self.to_representation(self.instance)
  File "/home/stocklap216/anaconda3/envs/django_env/lib/python3.7/site-packages/rest_framework/serializers.py", line 664, in to_representation
    self.child.to_representation(item) for item in iterable
TypeError: 'Company' object is not iterable
ERROR 2021-12-29 02:55:34,396 basehttp 78054 140054739506944 "GET /api/company/ HTTP/1.1" 500 109327
ERROR 2021-12-29 03:00:35,141 log 79717 140262484055808 Internal Server Error: /api/company/
Traceback (most recent call last):
  File "/home/stocklap216/anaconda3/envs/django_env/lib/python3.7/site-packages/django/core/handlers/exception.py", line 47, in inner
    response = get_response(request)
  File "/home/stocklap216/anaconda3/envs/django_env/lib/python3.7/site-packages/django/core/handlers/base.py", line 181, in _get_response
    response = wrapped_callback(request, *callback_args, **callback_kwargs)
  File "/home/stocklap216/anaconda3/envs/django_env/lib/python3.7/site-packages/django/views/decorators/csrf.py", line 54, in wrapped_view
    return view_func(*args, **kwargs)
  File "/home/stocklap216/anaconda3/envs/django_env/lib/python3.7/site-packages/rest_framework/viewsets.py", line 125, in view
    return self.dispatch(request, *args, **kwargs)
  File "/home/stocklap216/anaconda3/envs/django_env/lib/python3.7/site-packages/rest_framework/views.py", line 509, in dispatch
    response = self.handle_exception(exc)
  File "/home/stocklap216/anaconda3/envs/django_env/lib/python3.7/site-packages/rest_framework/views.py", line 469, in handle_exception
    self.raise_uncaught_exception(exc)
  File "/home/stocklap216/anaconda3/envs/django_env/lib/python3.7/site-packages/rest_framework/views.py", line 480, in raise_uncaught_exception
    raise exc
  File "/home/stocklap216/anaconda3/envs/django_env/lib/python3.7/site-packages/rest_framework/views.py", line 506, in dispatch
    response = handler(request, *args, **kwargs)
  File "/home/stocklap216/Documentos/Vacant/DJ/FlinkTest/backend/FlinkBackend/backendCRUD/views.py", line 68, in list
    print(serializer.data['valCompany'].replace("'","").replace("[","").replace("]","").split(",").stript())
AttributeError: 'list' object has no attribute 'stript'
ERROR 2021-12-29 03:00:35,142 basehttp 79717 140262484055808 "GET /api/company/ HTTP/1.1" 500 95780
ERROR 2021-12-29 03:00:59,058 log 79858 140310826931968 Internal Server Error: /api/company/
Traceback (most recent call last):
  File "/home/stocklap216/anaconda3/envs/django_env/lib/python3.7/site-packages/django/core/handlers/exception.py", line 47, in inner
    response = get_response(request)
  File "/home/stocklap216/anaconda3/envs/django_env/lib/python3.7/site-packages/django/core/handlers/base.py", line 181, in _get_response
    response = wrapped_callback(request, *callback_args, **callback_kwargs)
  File "/home/stocklap216/anaconda3/envs/django_env/lib/python3.7/site-packages/django/views/decorators/csrf.py", line 54, in wrapped_view
    return view_func(*args, **kwargs)
  File "/home/stocklap216/anaconda3/envs/django_env/lib/python3.7/site-packages/rest_framework/viewsets.py", line 125, in view
    return self.dispatch(request, *args, **kwargs)
  File "/home/stocklap216/anaconda3/envs/django_env/lib/python3.7/site-packages/rest_framework/views.py", line 509, in dispatch
    response = self.handle_exception(exc)
  File "/home/stocklap216/anaconda3/envs/django_env/lib/python3.7/site-packages/rest_framework/views.py", line 469, in handle_exception
    self.raise_uncaught_exception(exc)
  File "/home/stocklap216/anaconda3/envs/django_env/lib/python3.7/site-packages/rest_framework/views.py", line 480, in raise_uncaught_exception
    raise exc
  File "/home/stocklap216/anaconda3/envs/django_env/lib/python3.7/site-packages/rest_framework/views.py", line 506, in dispatch
    response = handler(request, *args, **kwargs)
  File "/home/stocklap216/Documentos/Vacant/DJ/FlinkTest/backend/FlinkBackend/backendCRUD/views.py", line 68, in list
    print(serializer.data['valCompany'].replace("'","").replace("[","").replace("]","").split(",").strip())
AttributeError: 'list' object has no attribute 'strip'
ERROR 2021-12-29 03:00:59,058 basehttp 79858 140310826931968 "GET /api/company/ HTTP/1.1" 500 95772
ERROR 2021-12-29 03:04:29,284 log 80480 140602558224128 Internal Server Error: /api/company/
Traceback (most recent call last):
  File "/home/stocklap216/anaconda3/envs/django_env/lib/python3.7/site-packages/django/core/handlers/exception.py", line 47, in inner
    response = get_response(request)
  File "/home/stocklap216/anaconda3/envs/django_env/lib/python3.7/site-packages/django/core/handlers/base.py", line 181, in _get_response
    response = wrapped_callback(request, *callback_args, **callback_kwargs)
  File "/home/stocklap216/anaconda3/envs/django_env/lib/python3.7/site-packages/django/views/decorators/csrf.py", line 54, in wrapped_view
    return view_func(*args, **kwargs)
  File "/home/stocklap216/anaconda3/envs/django_env/lib/python3.7/site-packages/rest_framework/viewsets.py", line 125, in view
    return self.dispatch(request, *args, **kwargs)
  File "/home/stocklap216/anaconda3/envs/django_env/lib/python3.7/site-packages/rest_framework/views.py", line 509, in dispatch
    response = self.handle_exception(exc)
  File "/home/stocklap216/anaconda3/envs/django_env/lib/python3.7/site-packages/rest_framework/views.py", line 469, in handle_exception
    self.raise_uncaught_exception(exc)
  File "/home/stocklap216/anaconda3/envs/django_env/lib/python3.7/site-packages/rest_framework/views.py", line 480, in raise_uncaught_exception
    raise exc
  File "/home/stocklap216/anaconda3/envs/django_env/lib/python3.7/site-packages/rest_framework/views.py", line 506, in dispatch
    response = handler(request, *args, **kwargs)
  File "/home/stocklap216/Documentos/Vacant/DJ/FlinkTest/backend/FlinkBackend/backendCRUD/views.py", line 66, in list
    companies = get_object_or_404(queryset)
  File "/home/stocklap216/anaconda3/envs/django_env/lib/python3.7/site-packages/django/shortcuts.py", line 76, in get_object_or_404
    return queryset.get(*args, **kwargs)
  File "/home/stocklap216/anaconda3/envs/django_env/lib/python3.7/site-packages/django/db/models/query.py", line 436, in get
    num if not limit or num < limit else 'more than %s' % (limit - 1),
backendCRUD.models.Company.MultipleObjectsReturned: get() returned more than one Company -- it returned 2!
ERROR 2021-12-29 03:04:29,503 basehttp 80480 140602558224128 "GET /api/company/ HTTP/1.1" 500 104312
ERROR 2021-12-29 03:05:00,312 log 80744 140116715210496 Internal Server Error: /api/company/
Traceback (most recent call last):
  File "/home/stocklap216/anaconda3/envs/django_env/lib/python3.7/site-packages/django/core/handlers/exception.py", line 47, in inner
    response = get_response(request)
  File "/home/stocklap216/anaconda3/envs/django_env/lib/python3.7/site-packages/django/core/handlers/base.py", line 181, in _get_response
    response = wrapped_callback(request, *callback_args, **callback_kwargs)
  File "/home/stocklap216/anaconda3/envs/django_env/lib/python3.7/site-packages/django/views/decorators/csrf.py", line 54, in wrapped_view
    return view_func(*args, **kwargs)
  File "/home/stocklap216/anaconda3/envs/django_env/lib/python3.7/site-packages/rest_framework/viewsets.py", line 125, in view
    return self.dispatch(request, *args, **kwargs)
  File "/home/stocklap216/anaconda3/envs/django_env/lib/python3.7/site-packages/rest_framework/views.py", line 509, in dispatch
    response = self.handle_exception(exc)
  File "/home/stocklap216/anaconda3/envs/django_env/lib/python3.7/site-packages/rest_framework/views.py", line 469, in handle_exception
    self.raise_uncaught_exception(exc)
  File "/home/stocklap216/anaconda3/envs/django_env/lib/python3.7/site-packages/rest_framework/views.py", line 480, in raise_uncaught_exception
    raise exc
  File "/home/stocklap216/anaconda3/envs/django_env/lib/python3.7/site-packages/rest_framework/views.py", line 506, in dispatch
    response = handler(request, *args, **kwargs)
  File "/home/stocklap216/Documentos/Vacant/DJ/FlinkTest/backend/FlinkBackend/backendCRUD/views.py", line 66, in list
    companies = get_object_or_404(queryset)
  File "/home/stocklap216/anaconda3/envs/django_env/lib/python3.7/site-packages/django/shortcuts.py", line 76, in get_object_or_404
    return queryset.get(*args, **kwargs)
  File "/home/stocklap216/anaconda3/envs/django_env/lib/python3.7/site-packages/django/db/models/query.py", line 436, in get
    num if not limit or num < limit else 'more than %s' % (limit - 1),
backendCRUD.models.Company.MultipleObjectsReturned: get() returned more than one Company -- it returned 2!
ERROR 2021-12-29 03:05:00,313 basehttp 80744 140116715210496 "GET /api/company/ HTTP/1.1" 500 104322
ERROR 2021-12-29 03:05:30,036 log 80849 140201289164544 Internal Server Error: /api/company/
Traceback (most recent call last):
  File "/home/stocklap216/anaconda3/envs/django_env/lib/python3.7/site-packages/django/core/handlers/exception.py", line 47, in inner
    response = get_response(request)
  File "/home/stocklap216/anaconda3/envs/django_env/lib/python3.7/site-packages/django/core/handlers/base.py", line 181, in _get_response
    response = wrapped_callback(request, *callback_args, **callback_kwargs)
  File "/home/stocklap216/anaconda3/envs/django_env/lib/python3.7/site-packages/django/views/decorators/csrf.py", line 54, in wrapped_view
    return view_func(*args, **kwargs)
  File "/home/stocklap216/anaconda3/envs/django_env/lib/python3.7/site-packages/rest_framework/viewsets.py", line 125, in view
    return self.dispatch(request, *args, **kwargs)
  File "/home/stocklap216/anaconda3/envs/django_env/lib/python3.7/site-packages/rest_framework/views.py", line 509, in dispatch
    response = self.handle_exception(exc)
  File "/home/stocklap216/anaconda3/envs/django_env/lib/python3.7/site-packages/rest_framework/views.py", line 469, in handle_exception
    self.raise_uncaught_exception(exc)
  File "/home/stocklap216/anaconda3/envs/django_env/lib/python3.7/site-packages/rest_framework/views.py", line 480, in raise_uncaught_exception
    raise exc
  File "/home/stocklap216/anaconda3/envs/django_env/lib/python3.7/site-packages/rest_framework/views.py", line 506, in dispatch
    response = handler(request, *args, **kwargs)
  File "/home/stocklap216/Documentos/Vacant/DJ/FlinkTest/backend/FlinkBackend/backendCRUD/views.py", line 66, in list
    companies = get_object_or_404(queryset)
  File "/home/stocklap216/anaconda3/envs/django_env/lib/python3.7/site-packages/django/shortcuts.py", line 76, in get_object_or_404
    return queryset.get(*args, **kwargs)
  File "/home/stocklap216/anaconda3/envs/django_env/lib/python3.7/site-packages/django/db/models/query.py", line 436, in get
    num if not limit or num < limit else 'more than %s' % (limit - 1),
backendCRUD.models.Company.MultipleObjectsReturned: get() returned more than one Company -- it returned 2!
ERROR 2021-12-29 03:05:30,037 basehttp 80849 140201289164544 "GET /api/company/ HTTP/1.1" 500 104330
ERROR 2021-12-29 16:17:45,361 basehttp 5870 140318299494144 You're accessing the development server over HTTPS, but it only supports HTTP.

ERROR 2021-12-29 16:17:45,415 basehttp 5870 140318299494144 You're accessing the development server over HTTPS, but it only supports HTTP.

ERROR 2021-12-29 16:18:50,012 basehttp 5870 140318299494144 You're accessing the development server over HTTPS, but it only supports HTTP.

ERROR 2021-12-29 16:18:50,012 basehttp 5870 140318299494144 You're accessing the development server over HTTPS, but it only supports HTTP.

ERROR 2021-12-29 17:06:26,512 views 9871 140255697667840 This QueryDict instance is immutable
ERROR 2021-12-29 17:06:26,512 log 9871 140255697667840 Internal Server Error: /api/company/
ERROR 2021-12-29 17:06:26,512 basehttp 9871 140255697667840 "POST /api/company/ HTTP/1.1" 500 0
ERROR 2021-12-29 17:07:36,547 views 9871 140255739614976 This QueryDict instance is immutable
ERROR 2021-12-29 17:07:36,548 log 9871 140255739614976 Internal Server Error: /api/company/
ERROR 2021-12-29 17:07:36,549 basehttp 9871 140255739614976 "POST /api/company/ HTTP/1.1" 500 0
ERROR 2021-12-29 17:10:27,251 views 9871 140255697667840 JSON parse error - Expecting value: line 1 column 1 (char 0)
ERROR 2021-12-29 17:10:27,251 log 9871 140255697667840 Internal Server Error: /api/company/
ERROR 2021-12-29 17:10:27,252 basehttp 9871 140255697667840 "POST /api/company/ HTTP/1.1" 500 0
ERROR 2021-12-29 23:08:21,075 views 37549 140461835089728 'valCompany'
ERROR 2021-12-29 23:08:21,106 log 37549 140461835089728 Internal Server Error: /api/company/
ERROR 2021-12-29 23:10:32,018 views 37927 140425338132224 'valCompany'
ERROR 2021-12-29 23:10:32,018 log 37927 140425338132224 Internal Server Error: /api/company/
ERROR 2021-12-29 23:10:32,019 basehttp 37927 140425338132224 "POST /api/company/ HTTP/1.1" 500 0
ERROR 2021-12-29 23:24:37,226 views 39909 139994455516992 object of type 'NoneType' has no len()
ERROR 2021-12-29 23:24:37,226 log 39909 139994455516992 Internal Server Error: /api/company/3da01714-7b29-4636-8d91-42b1e0b7d7a9/
